---
{"dg-publish":true,"permalink":"/CS计算机科学/后端开发/Python 调试/","noteIcon":"","created":"2024-06-22T22:30:28.696+08:00","updated":"2024-04-23T23:08:21.000+08:00"}
---


当你的代码结构中包含多个嵌套的函数调用，每个函数都有可能引发错误时，有效的错误处理变得尤为重要。合理地使用`try-except`块可以帮助你捕获和处理这些错误，确保程序的健壮性。以下是一些处理嵌套函数中错误的策略：

### 1. 在每个函数内部使用 `try-except`

在每个可能出错的函数内部添加`try-except`块，这样可以在错误发生时立即处理，防止错误向上层传播。这种方法可以在错误发生的地点就进行处理，但可能会导致代码重复和难以维护。

```python
def func1():
    try:
        # 可能出错的代码
        result = risky_operation()
        return result
    except Exception as e:
        print(f"Error in func1: {e}")
        return None

def func2():
    try:
        val = func1()
        # 使用 val 进行进一步的操作
        return val * 2
    except Exception as e:
        print(f"Error in func2: {e}")
        return None
```

### 2. 在最外层函数使用 `try-except`

如果你愿意让错误在调用栈中向上传播到一个更高层次的处理点，你可以在最外层函数中捕获所有从内部函数传出的异常。这种方式可以减少代码中的错误处理重复，使错误处理更集中。

```python
def func1():
    # 不在这里处理错误
    result = risky_operation()
    return result

def func2():
    val = func1()
    return val * 2

def main():
    try:
        result = func2()
        print(result)
    except Exception as e:
        print(f"Error occurred: {e}")
```

### 3. 使用装饰器统一处理错误

如果你的应用中有许多函数都需要相似的错误处理逻辑，你可以考虑使用装饰器来统一处理错误。这种方式可以大大减少代码重复，使函数本身更专注于业务逻辑。

```python
def error_handler(func):
    def wrapper(*args, **kwargs):
        try:
            return func(*args, **kwargs)
        except Exception as e:
            print(f"Error in {func.__name__}: {e}")
            return None
    return wrapper

@error_handler
def func1():
    return risky_operation()

@error_handler
def func2():
    val = func1()
    return val * 2
```

如果你希望使用装饰器来统一处理多个嵌套循环中的错误，并确保循环不会因为错误而提前终止，你可以定义一个装饰器来捕获和处理这些异常。装饰器会将函数包装在一个`try-except`块中，每次迭代都会执行这个块，从而确保循环继续进行，即使发生了异常。

以下是如何定义这种装饰器的步骤：

#### 1. 定义装饰器

我们可以创建一个装饰器，它会自动捕获指定的异常，并允许循环继续执行。这个装饰器会特别适用于处理循环中的函数调用。

```python
from functools import wraps

def handle_errors_in_loops(exception_type=Exception, handle_func=None):
    def decorator(func):
        @wraps(func)
        def wrapper(*args, **kwargs):
            try:
                return func(*args, **kwargs)
            except exception_type as e:
                if handle_func:
                    handle_func(e)
                else:
                    print(f"Error occurred: {e}")
        return wrapper
    return decorator
```

#### 2. 使用装饰器

你可以将这个装饰器应用到任何可能在循环中调用的函数上。如果函数在执行过程中抛出了异常，装饰器会捕获这个异常并根据你提供的处理函数来处理它（例如打印错误消息）。然后，控制权返回到循环，继续进行下一次迭代。

#### 3. 定义错误处理函数

你可以定义一个或多个错误处理函数，用于在捕获异常时执行自定义的逻辑。

```python
def print_error(e):
    print(f"Handled error: {e}")
```

#### 4. 使用装饰器

这是一个如何在代码中应用这个装饰器的例子：

```python
@handle_errors_in_loops(exception_type=IndexError, handle_func=print_error)
def process_item(items, index):
    print(items[index])  # 可能抛出 IndexError

items = [1, 2, 3]

for i in range(5):
    process_item(items, i)
```

在这个例子中，即使`process_item`因为索引越界而抛出`IndexError`，装饰器也会捕获这个异常，调用`print_error`来处理它，并允许循环继续执行。

### 4. 区分不同类型的异常

在使用`try-except`块时，尽量捕获具体的异常类型而非通用的`Exception`，这可以帮助你更精确地处理不同类型的错误，并且避免隐藏其他未考虑到的编程错误。

```python
try:
    # 代码块
except ValueError:
    # 处理 ValueError
except TypeError:
    # 处理 TypeError
except Exception as e:
    # 处理其他所有异常
    print(f"Unexpected error: {e}")
```

这些策略可以根据你的具体需求和代码结构灵活选择和应用，帮助你更有效地管理和处理程序中的错误。

如果你已经在最外层加入了`try-except`块但程序还是因为错误在内层函数中而暂停了，可能存在几个原因。

### 1. **异常未被正确捕获**

可能是因为在`exec_orders()`或其调用的其他函数中抛出了未被预料到的异常类型。例如，如果你只捕获了特定类型的异常（如`ValueError`或`IOError`），而实际发生的异常是另一种类型（如`RuntimeError`），那么这个异常将不会被捕获。

**解决方案**：确保你捕获了所有可能的异常类型，或者至少使用`Exception`来捕获所有非系统退出类异常：

```python
try:
    # 可能抛出异常的代码
except Exception as e:
    logger.error(f"捕获到异常：{e}")
```

### 2. **异步代码中的错误处理不足**

由于你使用的是`asyncio`和异步函数，错误可能是在一个异步任务中抛出的，而这个任务没有被正确的`try-except`块包围。

**解决方案**：确保在每个异步函数中都进行错误捕获，或者在调用异步函数时使用`try-except`：

```python
async def some_async_function():
    try:
        # 异步操作
    except Exception as e:
        logger.error(f"异步函数出错：{e}")
        raise  # 重新抛出异常如果你希望它被上级调用者捕获

# 在调用异步函数的地方捕获
try:
    await some_async_function()
except Exception as e:
    logger.error(f"调用异步函数时捕获到异常：{e}")
```

### 3. **异常在其他线程或进程中抛出**

如果你的应用使用了多线程或多进程，并且错误是在一个不同的线程或进程中发生的，那么主程序的`try-except`块可能无法捕获这些异常。

**解决方案**：确保每个线程或进程都有自己的错误处理机制。

### 4. **异常处理代码自身出现错误**

有时候，异常处理代码（即`except`块中的代码）自身可能也会出错。这种情况下，原始的异常可能会被新的异常覆盖。

**解决方案**：确保你的异常处理代码足够简单，不会引发新的错误。使用基本的日志记录和简单的错误恢复策略。

### 5. **监视未捕获异常**

为了确保没有遗漏任何异常，你可以考虑在程序入口处设置一个全局异常监视器。

```python
import asyncio

def handle_exception(loop, context):
    msg = context.get("exception", context["message"])
    print(f"Caught exception: {msg}")
    logger.error(f"Caught exception: {msg}")

loop = asyncio.get_event_loop()
loop.set_exception_handler(handle_exception)

# 运行你的异步主函数
loop.run_until_complete(main_async_function())
```

通过这些方法，你可以更全面地控制异常处理，确保程序即使在面对错误时也能继续运行。如果需要更具体的建议，请提供更详细的代码和错误信息。